WARNING:__main__:
*****************************************
Setting OMP_NUM_THREADS environment variable for each process to be 1 in default, to avoid your system being overloaded, please further tune the variable for optimal performance in your application as needed. 
*****************************************
Current dir exists, do you want to remove and refresh it?
Current dir exists, do you want to remove and refresh it?
Dir Not removed !
Traceback (most recent call last):
  File "main.py", line 315, in <module>
    processor = Processor(args)
  File "main.py", line 66, in __init__
    self.model, self.optimizer = self.loading()
  File "main.py", line 144, in loading
    self.device.set_device(self.arg.device)
AttributeError: 'torch.device' object has no attribute 'set_device'
WARNING:torch.distributed.elastic.multiprocessing.api:Sending process 2869585 closing signal SIGTERM
ERROR:torch.distributed.elastic.multiprocessing.api:failed (exitcode: 1) local_rank: 1 (pid: 2869586) of binary: /shared/home/xvoice/anaconda3/envs/signL/bin/python
Traceback (most recent call last):
  File "/shared/home/xvoice/anaconda3/envs/signL/lib/python3.8/runpy.py", line 194, in _run_module_as_main
    return _run_code(code, main_globals, None,
  File "/shared/home/xvoice/anaconda3/envs/signL/lib/python3.8/runpy.py", line 87, in _run_code
    exec(code, run_globals)
  File "/shared/home/xvoice/anaconda3/envs/signL/lib/python3.8/site-packages/torch/distributed/run.py", line 766, in <module>
    main()
  File "/shared/home/xvoice/anaconda3/envs/signL/lib/python3.8/site-packages/torch/distributed/elastic/multiprocessing/errors/__init__.py", line 346, in wrapper
    return f(*args, **kwargs)
  File "/shared/home/xvoice/anaconda3/envs/signL/lib/python3.8/site-packages/torch/distributed/run.py", line 762, in main
    run(args)
  File "/shared/home/xvoice/anaconda3/envs/signL/lib/python3.8/site-packages/torch/distributed/run.py", line 753, in run
    elastic_launch(
  File "/shared/home/xvoice/anaconda3/envs/signL/lib/python3.8/site-packages/torch/distributed/launcher/api.py", line 132, in __call__
    return launch_agent(self._config, self._entrypoint, list(args))
  File "/shared/home/xvoice/anaconda3/envs/signL/lib/python3.8/site-packages/torch/distributed/launcher/api.py", line 246, in launch_agent
    raise ChildFailedError(
torch.distributed.elastic.multiprocessing.errors.ChildFailedError: 
============================================================
main.py FAILED
------------------------------------------------------------
Failures:
  <NO_OTHER_FAILURES>
------------------------------------------------------------
Root Cause (first observed failure):
[0]:
  time      : 2025-07-16_18:50:57
  host      : a100-n3-eno2
  rank      : 1 (local_rank: 1)
  exitcode  : 1 (pid: 2869586)
  error_file: <N/A>
  traceback : To enable traceback see: https://pytorch.org/docs/stable/elastic/errors.html
============================================================
