WARNING:__main__:
*****************************************
Setting OMP_NUM_THREADS environment variable for each process to be 1 in default, to avoid your system being overloaded, please further tune the variable for optimal performance in your application as needed. 
*****************************************
Current dir exists, do you want to remove and refresh it?
Traceback (most recent call last):
Traceback (most recent call last):
  File "main.py", line 314, in <module>
  File "main.py", line 314, in <module>
    args.local_rank = setup_ddp()
  File "main.py", line 291, in setup_ddp
    args.local_rank = setup_ddp()
  File "main.py", line 291, in setup_ddp
    torch.cuda.set_device(local_rank)
  File "/shared/home/xvoice/anaconda3/envs/signL/lib/python3.8/site-packages/torch/cuda/__init__.py", line 326, in set_device
    torch.cuda.set_device(local_rank)
  File "/shared/home/xvoice/anaconda3/envs/signL/lib/python3.8/site-packages/torch/cuda/__init__.py", line 326, in set_device
    torch._C._cuda_setDevice(device)
RuntimeError: CUDA error: invalid device ordinal
CUDA kernel errors might be asynchronously reported at some other API call,so the stacktrace below might be incorrect.
For debugging consider passing CUDA_LAUNCH_BLOCKING=1.
    torch._C._cuda_setDevice(device)
RuntimeError: CUDA error: invalid device ordinal
CUDA kernel errors might be asynchronously reported at some other API call,so the stacktrace below might be incorrect.
For debugging consider passing CUDA_LAUNCH_BLOCKING=1.
Current dir exists, do you want to remove and refresh it?
WARNING:torch.distributed.elastic.multiprocessing.api:Sending process 2867765 closing signal SIGTERM
WARNING:torch.distributed.elastic.multiprocessing.api:Sending process 2867766 closing signal SIGTERM
ERROR:torch.distributed.elastic.multiprocessing.api:failed (exitcode: 1) local_rank: 2 (pid: 2867767) of binary: /shared/home/xvoice/anaconda3/envs/signL/bin/python
Traceback (most recent call last):
  File "/shared/home/xvoice/anaconda3/envs/signL/lib/python3.8/runpy.py", line 194, in _run_module_as_main
    return _run_code(code, main_globals, None,
  File "/shared/home/xvoice/anaconda3/envs/signL/lib/python3.8/runpy.py", line 87, in _run_code
    exec(code, run_globals)
  File "/shared/home/xvoice/anaconda3/envs/signL/lib/python3.8/site-packages/torch/distributed/run.py", line 766, in <module>
    main()
  File "/shared/home/xvoice/anaconda3/envs/signL/lib/python3.8/site-packages/torch/distributed/elastic/multiprocessing/errors/__init__.py", line 346, in wrapper
    return f(*args, **kwargs)
  File "/shared/home/xvoice/anaconda3/envs/signL/lib/python3.8/site-packages/torch/distributed/run.py", line 762, in main
    run(args)
  File "/shared/home/xvoice/anaconda3/envs/signL/lib/python3.8/site-packages/torch/distributed/run.py", line 753, in run
    elastic_launch(
  File "/shared/home/xvoice/anaconda3/envs/signL/lib/python3.8/site-packages/torch/distributed/launcher/api.py", line 132, in __call__
    return launch_agent(self._config, self._entrypoint, list(args))
  File "/shared/home/xvoice/anaconda3/envs/signL/lib/python3.8/site-packages/torch/distributed/launcher/api.py", line 246, in launch_agent
    raise ChildFailedError(
torch.distributed.elastic.multiprocessing.errors.ChildFailedError: 
============================================================
main.py FAILED
------------------------------------------------------------
Failures:
[1]:
  time      : 2025-07-16_18:46:57
  host      : a100-n3-eno2
  rank      : 3 (local_rank: 3)
  exitcode  : 1 (pid: 2867768)
  error_file: <N/A>
  traceback : To enable traceback see: https://pytorch.org/docs/stable/elastic/errors.html
------------------------------------------------------------
Root Cause (first observed failure):
[0]:
  time      : 2025-07-16_18:46:57
  host      : a100-n3-eno2
  rank      : 2 (local_rank: 2)
  exitcode  : 1 (pid: 2867767)
  error_file: <N/A>
  traceback : To enable traceback see: https://pytorch.org/docs/stable/elastic/errors.html
============================================================
